Workbook

Sheet Setup
A1: Once MFL 2024 is live

Sheet TVC-10

Sheet Tracker
C1: Team | D1: The Wild Cards | E1: Hamsterdam | F1: Shankly's Ghost | G1: 2 Roops, 1 Silva | H1: Orcan Terror | I1: The Meaty Ogres | J1: Ted Lasso | K1: Peaky Fookin Blinders | L1: Springfield Isotopes | M1: Battlebots | N1: The Two Tones | O1: Norsemen
B2: =sum(D2:O2) -> 210 | C2: Current Tokens | D2: =sum(D3:D996) -> 11 | E2: =sum(E3:E996) -> 13 | F2: =sum(F3:F996) -> 3 | G2: =sum(G3:G996) -> 12 | H2: =sum(H3:H996) -> 18 | I2: =sum(I3:I996) -> 16 | J2: =sum(J3:J996) -> 3 | K2: =sum(K3:K996) -> 0 | ... O2: =sum(O3:O996) -> 15
A3: Start | B3: 46037 | C3: Start of Year | D3: 11 | E3: 13 | F3: 0 | G3: 9 | H3: 15 | I3: 13 | J3: 3 | K3: 0 | L3: 20 | M3: 84 | N3: 11 | O3: 15
A4: Jan-Mar | B4: 46023 | C4: Trades | D4: =IFERROR(__xludf.DUMMYFUNCTION("IFNA(filter(Trades!$J:$J,Trades!$B:$B=D$1,Trades!$A:$A>=$B4,Trades!$A:$A<=$B6),0)+IFNA(filter(Trades!$J:$J,Trades!$F:$F=D$1,Trades!$A:$A>=$B4,Trades!$A:$A<=$B6),0)"),0.0) -> 0 | E4: =IFERROR(__xludf.DUMMYFUNCTION("IFNA(filter(Trades!$J:$J,Trades!$B:$B=E$1,Trades!$A:$A>=$B4,Trades!$A:$A<=$B6),0)+IFNA(filter(Trades!$J:$J,Trades!$F:$F=E$1,Trades!$A:$A>=$B4,Trades!$A:$A<=$B6),0)"),0.0) -> 0 | F4: =IFERROR(__xludf.DUMMYFUNCTION("IFNA(filter(Trades!$J:$J,Trades!$B:$B=F$1,Trades!$A:$A>=$B4,Trades!$A:$A<=$B6),0)+IFNA(filter(Trades!$J:$J,Trades!$F:$F=F$1,Trades!$A:$A>=$B4,Trades!$A:$A<=$B6),0)"),0.0) -> 0 | G4: =IFERROR(__xludf.DUMMYFUNCTION("IFNA(filter(Trades!$J:$J,Trades!$B:$B=G$1,Trades!$A:$A>=$B4,Trades!$A:$A<=$B6),0)+IFNA(filter(Trades!$J:$J,Trades!$F:$F=G$1,Trades!$A:$A>=$B4,Trades!$A:$A<=$B6),0)"),0.0) -> 0 | H4: =IFERROR(__xludf.DUMMYFUNCTION("IFNA(filter(Trades!$J:$J,Trades!$B:$B=H$1,Trades!$A:$A>=$B4,Trades!$A:$A<=$B6),0)+IFNA(filter(Trades!$J:$J,Trades!$F:$F=H$1,Trades!$A:$A>=$B4,Trades!$A:$A<=$B6),0)"),0.0) -> 0 | I4: =IFERROR(__xludf.DUMMYFUNCTION("IFNA(filter(Trades!$J:$J,Trades!$B:$B=I$1,Trades!$A:$A>=$B4,Trades!$A:$A<=$B6),0)+IFNA(filter(Trades!$J:$J,Trades!$F:$F=I$1,Trades!$A:$A>=$B4,Trades!$A:$A<=$B6),0)"),0.0) -> 0 | J4: =IFERROR(__xludf.DUMMYFUNCTION("IFNA(filter(Trades!$J:$J,Trades!$B:$B=J$1,Trades!$A:$A>=$B4,Trades!$A:$A<=$B6),0)+IFNA(filter(Trades!$J:$J,Trades!$F:$F=J$1,Trades!$A:$A>=$B4,Trades!$A:$A<=$B6),0)"),0.0) -> 0 | K4: =IFERROR(__xludf.DUMMYFUNCTION("IFNA(filter(Trades!$J:$J,Trades!$B:$B=K$1,Trades!$A:$A>=$B4,Trades!$A:$A<=$B6),0)+IFNA(filter(Trades!$J:$J,Trades!$F:$F=K$1,Trades!$A:$A>=$B4,Trades!$A:$A<=$B6),0)"),0.0) -> 0 | L4: =IFERROR(__xludf.DUMMYFUNCTION("IFNA(filter(Trades!$J:$J,Trades!$B:$B=L$1,Trades!$A:$A>=$B4,Trades!$A:$A<=$B6),0)+IFNA(filter(Trades!$J:$J,Trades!$F:$F=L$1,Trades!$A:$A>=$B4,Trades!$A:$A<=$B6),0)"),0.0) -> 0 | M4: =IFERROR(__xludf.DUMMYFUNCTION("IFNA(filter(Trades!$J:$J,Trades!$B:$B=M$1,Trades!$A:$A>=$B4,Trades!$A:$A<=$B6),0)+IFNA(filter(Trades!$J:$J,Trades!$F:$F=M$1,Trades!$A:$A>=$B4,Trades!$A:$A<=$B6),0)"),0.0) -> 0 | N4: =IFERROR(__xludf.DUMMYFUNCTION("IFNA(filter(Trades!$J:$J,Trades!$B:$B=N$1,Trades!$A:$A>=$B4,Trades!$A:$A<=$B6),0)+IFNA(filter(Trades!$J:$J,Trades!$F:$F=N$1,Trades!$A:$A>=$B4,Trades!$A:$A<=$B6),0)"),0.0) -> 0 | O4: =IFERROR(__xludf.DUMMYFUNCTION("IFNA(filter(Trades!$J:$J,Trades!$B:$B=O$1,Trades!$A:$A>=$B4,Trades!$A:$A<=$B6),0)+IFNA(filter(Trades!$J:$J,Trades!$F:$F=O$1,Trades!$A:$A>=$B4,Trades!$A:$A<=$B6),0)"),0.0) -> 0
C5: Tokens Traded/Voided
B6: 46112
A7: Apr-Jun | B7: 46113 | C7: Trades | D7: =IFERROR(__xludf.DUMMYFUNCTION("IFNA(filter(Trades!$J:$J,Trades!$B:$B=D$1,Trades!$A:$A>=$B7,Trades!$A:$A<=$B9),0)+IFNA(filter(Trades!$J:$J,Trades!$F:$F=D$1,Trades!$A:$A>=$B7,Trades!$A:$A<=$B9),0)"),0.0) -> 0 | E7: =IFERROR(__xludf.DUMMYFUNCTION("IFNA(filter(Trades!$J:$J,Trades!$B:$B=E$1,Trades!$A:$A>=$B7,Trades!$A:$A<=$B9),0)+IFNA(filter(Trades!$J:$J,Trades!$F:$F=E$1,Trades!$A:$A>=$B7,Trades!$A:$A<=$B9),0)"),0.0) -> 0 | F7: =IFERROR(__xludf.DUMMYFUNCTION("IFNA(filter(Trades!$J:$J,Trades!$B:$B=F$1,Trades!$A:$A>=$B7,Trades!$A:$A<=$B9),0)+IFNA(filter(Trades!$J:$J,Trades!$F:$F=F$1,Trades!$A:$A>=$B7,Trades!$A:$A<=$B9),0)"),0.0) -> 0 | G7: =IFERROR(__xludf.DUMMYFUNCTION("IFNA(filter(Trades!$J:$J,Trades!$B:$B=G$1,Trades!$A:$A>=$B7,Trades!$A:$A<=$B9),0)+IFNA(filter(Trades!$J:$J,Trades!$F:$F=G$1,Trades!$A:$A>=$B7,Trades!$A:$A<=$B9),0)"),0.0) -> 0 | H7: =IFERROR(__xludf.DUMMYFUNCTION("IFNA(filter(Trades!$J:$J,Trades!$B:$B=H$1,Trades!$A:$A>=$B7,Trades!$A:$A<=$B9),0)+IFNA(filter(Trades!$J:$J,Trades!$F:$F=H$1,Trades!$A:$A>=$B7,Trades!$A:$A<=$B9),0)"),0.0) -> 0 | I7: =IFERROR(__xludf.DUMMYFUNCTION("IFNA(filter(Trades!$J:$J,Trades!$B:$B=I$1,Trades!$A:$A>=$B7,Trades!$A:$A<=$B9),0)+IFNA(filter(Trades!$J:$J,Trades!$F:$F=I$1,Trades!$A:$A>=$B7,Trades!$A:$A<=$B9),0)"),0.0) -> 0 | J7: =IFERROR(__xludf.DUMMYFUNCTION("IFNA(filter(Trades!$J:$J,Trades!$B:$B=J$1,Trades!$A:$A>=$B7,Trades!$A:$A<=$B9),0)+IFNA(filter(Trades!$J:$J,Trades!$F:$F=J$1,Trades!$A:$A>=$B7,Trades!$A:$A<=$B9),0)"),0.0) -> 0 | K7: =IFERROR(__xludf.DUMMYFUNCTION("IFNA(filter(Trades!$J:$J,Trades!$B:$B=K$1,Trades!$A:$A>=$B7,Trades!$A:$A<=$B9),0)+IFNA(filter(Trades!$J:$J,Trades!$F:$F=K$1,Trades!$A:$A>=$B7,Trades!$A:$A<=$B9),0)"),0.0) -> 0 | L7: =IFERROR(__xludf.DUMMYFUNCTION("IFNA(filter(Trades!$J:$J,Trades!$B:$B=L$1,Trades!$A:$A>=$B7,Trades!$A:$A<=$B9),0)+IFNA(filter(Trades!$J:$J,Trades!$F:$F=L$1,Trades!$A:$A>=$B7,Trades!$A:$A<=$B9),0)"),0.0) -> 0 | M7: =IFERROR(__xludf.DUMMYFUNCTION("IFNA(filter(Trades!$J:$J,Trades!$B:$B=M$1,Trades!$A:$A>=$B7,Trades!$A:$A<=$B9),0)+IFNA(filter(Trades!$J:$J,Trades!$F:$F=M$1,Trades!$A:$A>=$B7,Trades!$A:$A<=$B9),0)"),0.0) -> 0 | N7: =IFERROR(__xludf.DUMMYFUNCTION("IFNA(filter(Trades!$J:$J,Trades!$B:$B=N$1,Trades!$A:$A>=$B7,Trades!$A:$A<=$B9),0)+IFNA(filter(Trades!$J:$J,Trades!$F:$F=N$1,Trades!$A:$A>=$B7,Trades!$A:$A<=$B9),0)"),0.0) -> 0 | O7: =IFERROR(__xludf.DUMMYFUNCTION("IFNA(filter(Trades!$J:$J,Trades!$B:$B=O$1,Trades!$A:$A>=$B7,Trades!$A:$A<=$B9),0)+IFNA(filter(Trades!$J:$J,Trades!$F:$F=O$1,Trades!$A:$A>=$B7,Trades!$A:$A<=$B9),0)"),0.0) -> 0
C8: Tokens Traded
B9: 46203
A10: Jul-Wk1 | B10: 46204 | C10: Trades | D10: =IFERROR(__xludf.DUMMYFUNCTION("IFNA(filter(Trades!$J:$J,Trades!$B:$B=D$1,Trades!$A:$A>=$B10,Trades!$A:$A<=$B12),0)+IFNA(filter(Trades!$J:$J,Trades!$F:$F=D$1,Trades!$A:$A>=$B10,Trades!$A:$A<=$B12),0)"),0.0) -> 0 | E10: =IFERROR(__xludf.DUMMYFUNCTION("IFNA(filter(Trades!$J:$J,Trades!$B:$B=E$1,Trades!$A:$A>=$B10,Trades!$A:$A<=$B12),0)+IFNA(filter(Trades!$J:$J,Trades!$F:$F=E$1,Trades!$A:$A>=$B10,Trades!$A:$A<=$B12),0)"),0.0) -> 0 | F10: =IFERROR(__xludf.DUMMYFUNCTION("IFNA(filter(Trades!$J:$J,Trades!$B:$B=F$1,Trades!$A:$A>=$B10,Trades!$A:$A<=$B12),0)+IFNA(filter(Trades!$J:$J,Trades!$F:$F=F$1,Trades!$A:$A>=$B10,Trades!$A:$A<=$B12),0)"),0.0) -> 0 | G10: =IFERROR(__xludf.DUMMYFUNCTION("IFNA(filter(Trades!$J:$J,Trades!$B:$B=G$1,Trades!$A:$A>=$B10,Trades!$A:$A<=$B12),0)+IFNA(filter(Trades!$J:$J,Trades!$F:$F=G$1,Trades!$A:$A>=$B10,Trades!$A:$A<=$B12),0)"),0.0) -> 0 | H10: =IFERROR(__xludf.DUMMYFUNCTION("IFNA(filter(Trades!$J:$J,Trades!$B:$B=H$1,Trades!$A:$A>=$B10,Trades!$A:$A<=$B12),0)+IFNA(filter(Trades!$J:$J,Trades!$F:$F=H$1,Trades!$A:$A>=$B10,Trades!$A:$A<=$B12),0)"),0.0) -> 0 | I10: =IFERROR(__xludf.DUMMYFUNCTION("IFNA(filter(Trades!$J:$J,Trades!$B:$B=I$1,Trades!$A:$A>=$B10,Trades!$A:$A<=$B12),0)+IFNA(filter(Trades!$J:$J,Trades!$F:$F=I$1,Trades!$A:$A>=$B10,Trades!$A:$A<=$B12),0)"),0.0) -> 0 | J10: =IFERROR(__xludf.DUMMYFUNCTION("IFNA(filter(Trades!$J:$J,Trades!$B:$B=J$1,Trades!$A:$A>=$B10,Trades!$A:$A<=$B12),0)+IFNA(filter(Trades!$J:$J,Trades!$F:$F=J$1,Trades!$A:$A>=$B10,Trades!$A:$A<=$B12),0)"),0.0) -> 0 | K10: =IFERROR(__xludf.DUMMYFUNCTION("IFNA(filter(Trades!$J:$J,Trades!$B:$B=K$1,Trades!$A:$A>=$B10,Trades!$A:$A<=$B12),0)+IFNA(filter(Trades!$J:$J,Trades!$F:$F=K$1,Trades!$A:$A>=$B10,Trades!$A:$A<=$B12),0)"),0.0) -> 0 | L10: =IFERROR(__xludf.DUMMYFUNCTION("IFNA(filter(Trades!$J:$J,Trades!$B:$B=L$1,Trades!$A:$A>=$B10,Trades!$A:$A<=$B12),0)+IFNA(filter(Trades!$J:$J,Trades!$F:$F=L$1,Trades!$A:$A>=$B10,Trades!$A:$A<=$B12),0)"),0.0) -> 0 | M10: =IFERROR(__xludf.DUMMYFUNCTION("IFNA(filter(Trades!$J:$J,Trades!$B:$B=M$1,Trades!$A:$A>=$B10,Trades!$A:$A<=$B12),0)+IFNA(filter(Trades!$J:$J,Trades!$F:$F=M$1,Trades!$A:$A>=$B10,Trades!$A:$A<=$B12),0)"),0.0) -> 0 | N10: =IFERROR(__xludf.DUMMYFUNCTION("IFNA(filter(Trades!$J:$J,Trades!$B:$B=N$1,Trades!$A:$A>=$B10,Trades!$A:$A<=$B12),0)+IFNA(filter(Trades!$J:$J,Trades!$F:$F=N$1,Trades!$A:$A>=$B10,Trades!$A:$A<=$B12),0)"),0.0) -> 0 | O10: =IFERROR(__xludf.DUMMYFUNCTION("IFNA(filter(Trades!$J:$J,Trades!$B:$B=O$1,Trades!$A:$A>=$B10,Trades!$A:$A<=$B12),0)+IFNA(filter(Trades!$J:$J,Trades!$F:$F=O$1,Trades!$A:$A>=$B10,Trades!$A:$A<=$B12),0)"),0.0) -> 0
C11: Tokens Traded | K11: -2 | M11: -2
B12: 46266
A13: Q1 Reg | B13: 46267 | C13: Trades | D13: =IFERROR(__xludf.DUMMYFUNCTION("IFNA(filter(Trades!$J:$J,Trades!$B:$B=D$1,Trades!$A:$A>=$B13,Trades!$A:$A<=$B16),0)+IFNA(filter(Trades!$J:$J,Trades!$F:$F=D$1,Trades!$A:$A>=$B13,Trades!$A:$A<=$B16),0)"),0.0) -> 0 | E13: =IFERROR(__xludf.DUMMYFUNCTION("IFNA(filter(Trades!$J:$J,Trades!$B:$B=E$1,Trades!$A:$A>=$B13,Trades!$A:$A<=$B15),0)+IFNA(filter(Trades!$J:$J,Trades!$F:$F=E$1,Trades!$A:$A>=$B13,Trades!$A:$A<=$B15),0)"),0.0) -> 0 | F13: =IFERROR(__xludf.DUMMYFUNCTION("IFNA(filter(Trades!$J:$J,Trades!$B:$B=F$1,Trades!$A:$A>=$B13,Trades!$A:$A<=$B15),0)+IFNA(filter(Trades!$J:$J,Trades!$F:$F=F$1,Trades!$A:$A>=$B13,Trades!$A:$A<=$B15),0)"),0.0) -> 0 | G13: =IFERROR(__xludf.DUMMYFUNCTION("IFNA(filter(Trades!$J:$J,Trades!$B:$B=G$1,Trades!$A:$A>=$B13,Trades!$A:$A<=$B15),0)+IFNA(filter(Trades!$J:$J,Trades!$F:$F=G$1,Trades!$A:$A>=$B13,Trades!$A:$A<=$B15),0)"),0.0) -> 0 | H13: =IFERROR(__xludf.DUMMYFUNCTION("IFNA(filter(Trades!$J:$J,Trades!$B:$B=H$1,Trades!$A:$A>=$B13,Trades!$A:$A<=$B15),0)+IFNA(filter(Trades!$J:$J,Trades!$F:$F=H$1,Trades!$A:$A>=$B13,Trades!$A:$A<=$B15),0)"),0.0) -> 0 | I13: =IFERROR(__xludf.DUMMYFUNCTION("IFNA(filter(Trades!$J:$J,Trades!$B:$B=I$1,Trades!$A:$A>=$B13,Trades!$A:$A<=$B15),0)+IFNA(filter(Trades!$J:$J,Trades!$F:$F=I$1,Trades!$A:$A>=$B13,Trades!$A:$A<=$B15),0)"),0.0) -> 0 | J13: =IFERROR(__xludf.DUMMYFUNCTION("IFNA(filter(Trades!$J:$J,Trades!$B:$B=J$1,Trades!$A:$A>=$B13,Trades!$A:$A<=$B15),0)+IFNA(filter(Trades!$J:$J,Trades!$F:$F=J$1,Trades!$A:$A>=$B13,Trades!$A:$A<=$B15),0)"),0.0) -> 0 | K13: =IFERROR(__xludf.DUMMYFUNCTION("IFNA(filter(Trades!$J:$J,Trades!$B:$B=K$1,Trades!$A:$A>=$B13,Trades!$A:$A<=$B15),0)+IFNA(filter(Trades!$J:$J,Trades!$F:$F=K$1,Trades!$A:$A>=$B13,Trades!$A:$A<=$B15),0)"),0.0) -> 0 | L13: =IFERROR(__xludf.DUMMYFUNCTION("IFNA(filter(Trades!$J:$J,Trades!$B:$B=L$1,Trades!$A:$A>=$B13,Trades!$A:$A<=$B15),0)+IFNA(filter(Trades!$J:$J,Trades!$F:$F=L$1,Trades!$A:$A>=$B13,Trades!$A:$A<=$B15),0)"),0.0) -> 0 | M13: =IFERROR(__xludf.DUMMYFUNCTION("IFNA(filter(Trades!$J:$J,Trades!$B:$B=M$1,Trades!$A:$A>=$B13,Trades!$A:$A<=$B15),0)+IFNA(filter(Trades!$J:$J,Trades!$F:$F=M$1,Trades!$A:$A>=$B13,Trades!$A:$A<=$B15),0)"),0.0) -> 0 | N13: =IFERROR(__xludf.DUMMYFUNCTION("IFNA(filter(Trades!$J:$J,Trades!$B:$B=N$1,Trades!$A:$A>=$B13,Trades!$A:$A<=$B15),0)+IFNA(filter(Trades!$J:$J,Trades!$F:$F=N$1,Trades!$A:$A>=$B13,Trades!$A:$A<=$B15),0)"),0.0) -> 0 | O13: =IFERROR(__xludf.DUMMYFUNCTION("IFNA(filter(Trades!$J:$J,Trades!$B:$B=O$1,Trades!$A:$A>=$B13,Trades!$A:$A<=$B15),0)+IFNA(filter(Trades!$J:$J,Trades!$F:$F=O$1,Trades!$A:$A>=$B13,Trades!$A:$A<=$B15),0)"),0.0) -> 0
C14: Tokens Traded
C15: Adds >= $25 | D15: =IF(countifs(Waivers!$B:$B,"="&D$1,Waivers!$F:$F,">"&datevalue($B12-1),Waivers!$F:$F,"<"&datevalue($B16+1),Waivers!$G:$G,">9")>4,5,countifs(Waivers!$B:$B,"="&D$1,Waivers!$F:$F,">"&datevalue($B12-1),Waivers!$F:$F,"<"&datevalue($B16+1),Waivers!$G:$G,">9")) -> 0 | E15: =IF(countifs(Waivers!$B:$B,"="&E$1,Waivers!$F:$F,">"&datevalue($B12-1),Waivers!$F:$F,"<"&datevalue($B16+1),Waivers!$G:$G,">9")>4,5,countifs(Waivers!$B:$B,"="&E$1,Waivers!$F:$F,">"&datevalue($B12-1),Waivers!$F:$F,"<"&datevalue($B16+1),Waivers!$G:$G,">9")) -> 0 | F15: =IF(countifs(Waivers!$B:$B,"="&F$1,Waivers!$F:$F,">"&datevalue($B12-1),Waivers!$F:$F,"<"&datevalue($B16+1),Waivers!$G:$G,">9")>4,5,countifs(Waivers!$B:$B,"="&F$1,Waivers!$F:$F,">"&datevalue($B12-1),Waivers!$F:$F,"<"&datevalue($B16+1),Waivers!$G:$G,">9")) -> 3 | G15: =IF(countifs(Waivers!$B:$B,"="&G$1,Waivers!$F:$F,">"&datevalue($B12-1),Waivers!$F:$F,"<"&datevalue($B16+1),Waivers!$G:$G,">9")>4,5,countifs(Waivers!$B:$B,"="&G$1,Waivers!$F:$F,">"&datevalue($B12-1),Waivers!$F:$F,"<"&datevalue($B16+1),Waivers!$G:$G,">9")) -> 3 | H15: =IF(countifs(Waivers!$B:$B,"="&H$1,Waivers!$F:$F,">"&datevalue($B12-1),Waivers!$F:$F,"<"&datevalue($B16+1),Waivers!$G:$G,">9")>4,5,countifs(Waivers!$B:$B,"="&H$1,Waivers!$F:$F,">"&datevalue($B12-1),Waivers!$F:$F,"<"&datevalue($B16+1),Waivers!$G:$G,">9")) -> 1 | I15: =IF(countifs(Waivers!$B:$B,"="&I$1,Waivers!$F:$F,">"&datevalue($B12-1),Waivers!$F:$F,"<"&datevalue($B16+1),Waivers!$G:$G,">9")>4,5,countifs(Waivers!$B:$B,"="&I$1,Waivers!$F:$F,">"&datevalue($B12-1),Waivers!$F:$F,"<"&datevalue($B16+1),Waivers!$G:$G,">9")) -> 3 | J15: =IF(countifs(Waivers!$B:$B,"="&J$1,Waivers!$F:$F,">"&datevalue($B12-1),Waivers!$F:$F,"<"&datevalue($B16+1),Waivers!$G:$G,">9")>4,5,countifs(Waivers!$B:$B,"="&J$1,Waivers!$F:$F,">"&datevalue($B12-1),Waivers!$F:$F,"<"&datevalue($B16+1),Waivers!$G:$G,">9")) -> 0 | K15: =IF(countifs(Waivers!$B:$B,"="&K$1,Waivers!$F:$F,">"&datevalue($B12-1),Waivers!$F:$F,"<"&datevalue($B16+1),Waivers!$G:$G,">9")>4,5,countifs(Waivers!$B:$B,"="&K$1,Waivers!$F:$F,">"&datevalue($B12-1),Waivers!$F:$F,"<"&datevalue($B16+1),Waivers!$G:$G,">9")) -> 1 | ... O15: =IF(countifs(Waivers!$B:$B,"="&O$1,Waivers!$F:$F,">"&datevalue($B12-1),Waivers!$F:$F,"<"&datevalue($B16+1),Waivers!$G:$G,">9")>4,5,countifs(Waivers!$B:$B,"="&O$1,Waivers!$F:$F,">"&datevalue($B12-1),Waivers!$F:$F,"<"&datevalue($B16+1),Waivers!$G:$G,">9")) -> 0
B16: 46293 | C16: Promotion Award
A17: Q2 Reg | B17: 46294 | C17: Trades | D17: =IFERROR(__xludf.DUMMYFUNCTION("IFNA(filter(Trades!$J:$J,Trades!$B:$B=D$1,Trades!$A:$A>=$B17,Trades!$A:$A<=$B20),0)+IFNA(filter(Trades!$J:$J,Trades!$F:$F=D$1,Trades!$A:$A>=$B17,Trades!$A:$A<=$B20),0)"),0.0) -> 0 | E17: =IFERROR(__xludf.DUMMYFUNCTION("IFNA(filter(Trades!$J:$J,Trades!$B:$B=E$1,Trades!$A:$A>=$B17,Trades!$A:$A<=$B19),0)+IFNA(filter(Trades!$J:$J,Trades!$F:$F=E$1,Trades!$A:$A>=$B17,Trades!$A:$A<=$B19),0)"),0.0) -> 0 | F17: =IFERROR(__xludf.DUMMYFUNCTION("IFNA(filter(Trades!$J:$J,Trades!$B:$B=F$1,Trades!$A:$A>=$B17,Trades!$A:$A<=$B19),0)+IFNA(filter(Trades!$J:$J,Trades!$F:$F=F$1,Trades!$A:$A>=$B17,Trades!$A:$A<=$B19),0)"),0.0) -> 0 | G17: =IFERROR(__xludf.DUMMYFUNCTION("IFNA(filter(Trades!$J:$J,Trades!$B:$B=G$1,Trades!$A:$A>=$B17,Trades!$A:$A<=$B19),0)+IFNA(filter(Trades!$J:$J,Trades!$F:$F=G$1,Trades!$A:$A>=$B17,Trades!$A:$A<=$B19),0)"),0.0) -> 0 | H17: =IFERROR(__xludf.DUMMYFUNCTION("IFNA(filter(Trades!$J:$J,Trades!$B:$B=H$1,Trades!$A:$A>=$B17,Trades!$A:$A<=$B19),0)+IFNA(filter(Trades!$J:$J,Trades!$F:$F=H$1,Trades!$A:$A>=$B17,Trades!$A:$A<=$B19),0)"),0.0) -> 0 | I17: =IFERROR(__xludf.DUMMYFUNCTION("IFNA(filter(Trades!$J:$J,Trades!$B:$B=I$1,Trades!$A:$A>=$B17,Trades!$A:$A<=$B19),0)+IFNA(filter(Trades!$J:$J,Trades!$F:$F=I$1,Trades!$A:$A>=$B17,Trades!$A:$A<=$B19),0)"),0.0) -> 0 | J17: =IFERROR(__xludf.DUMMYFUNCTION("IFNA(filter(Trades!$J:$J,Trades!$B:$B=J$1,Trades!$A:$A>=$B17,Trades!$A:$A<=$B19),0)+IFNA(filter(Trades!$J:$J,Trades!$F:$F=J$1,Trades!$A:$A>=$B17,Trades!$A:$A<=$B19),0)"),0.0) -> 0 | K17: =IFERROR(__xludf.DUMMYFUNCTION("IFNA(filter(Trades!$J:$J,Trades!$B:$B=K$1,Trades!$A:$A>=$B17,Trades!$A:$A<=$B19),0)+IFNA(filter(Trades!$J:$J,Trades!$F:$F=K$1,Trades!$A:$A>=$B17,Trades!$A:$A<=$B19),0)"),0.0) -> 0 | L17: =IFERROR(__xludf.DUMMYFUNCTION("IFNA(filter(Trades!$J:$J,Trades!$B:$B=L$1,Trades!$A:$A>=$B17,Trades!$A:$A<=$B19),0)+IFNA(filter(Trades!$J:$J,Trades!$F:$F=L$1,Trades!$A:$A>=$B17,Trades!$A:$A<=$B19),0)"),0.0) -> 0 | M17: =IFERROR(__xludf.DUMMYFUNCTION("IFNA(filter(Trades!$J:$J,Trades!$B:$B=M$1,Trades!$A:$A>=$B17,Trades!$A:$A<=$B19),0)+IFNA(filter(Trades!$J:$J,Trades!$F:$F=M$1,Trades!$A:$A>=$B17,Trades!$A:$A<=$B19),0)"),0.0) -> 0 | N17: =IFERROR(__xludf.DUMMYFUNCTION("IFNA(filter(Trades!$J:$J,Trades!$B:$B=N$1,Trades!$A:$A>=$B17,Trades!$A:$A<=$B19),0)+IFNA(filter(Trades!$J:$J,Trades!$F:$F=N$1,Trades!$A:$A>=$B17,Trades!$A:$A<=$B19),0)"),0.0) -> 0 | O17: =IFERROR(__xludf.DUMMYFUNCTION("IFNA(filter(Trades!$J:$J,Trades!$B:$B=O$1,Trades!$A:$A>=$B17,Trades!$A:$A<=$B19),0)+IFNA(filter(Trades!$J:$J,Trades!$F:$F=O$1,Trades!$A:$A>=$B17,Trades!$A:$A<=$B19),0)"),0.0) -> 0
C18: Tokens Traded/Voided
C19: Adds >= $25 | D19: =IF(countifs(Waivers!$B:$B,"="&D$1,Waivers!$F:$F,">"&datevalue($B16-1),Waivers!$F:$F,"<"&datevalue($B20+1),Waivers!$G:$G,">9")>4,5,countifs(Waivers!$B:$B,"="&D$1,Waivers!$F:$F,">"&datevalue($B16-1),Waivers!$F:$F,"<"&datevalue($B20+1),Waivers!$G:$G,">9")) -> 0 | E19: =IF(countifs(Waivers!$B:$B,"="&E$1,Waivers!$F:$F,">"&datevalue($B16-1),Waivers!$F:$F,"<"&datevalue($B20+1),Waivers!$G:$G,">9")>4,5,countifs(Waivers!$B:$B,"="&E$1,Waivers!$F:$F,">"&datevalue($B16-1),Waivers!$F:$F,"<"&datevalue($B20+1),Waivers!$G:$G,">9")) -> 0 | F19: =IF(countifs(Waivers!$B:$B,"="&F$1,Waivers!$F:$F,">"&datevalue($B16-1),Waivers!$F:$F,"<"&datevalue($B20+1),Waivers!$G:$G,">9")>4,5,countifs(Waivers!$B:$B,"="&F$1,Waivers!$F:$F,">"&datevalue($B16-1),Waivers!$F:$F,"<"&datevalue($B20+1),Waivers!$G:$G,">9")) -> 0 | G19: =IF(countifs(Waivers!$B:$B,"="&G$1,Waivers!$F:$F,">"&datevalue($B16-1),Waivers!$F:$F,"<"&datevalue($B20+1),Waivers!$G:$G,">9")>4,5,countifs(Waivers!$B:$B,"="&G$1,Waivers!$F:$F,">"&datevalue($B16-1),Waivers!$F:$F,"<"&datevalue($B20+1),Waivers!$G:$G,">9")) -> 0 | H19: =IF(countifs(Waivers!$B:$B,"="&H$1,Waivers!$F:$F,">"&datevalue($B16-1),Waivers!$F:$F,"<"&datevalue($B20+1),Waivers!$G:$G,">9")>4,5,countifs(Waivers!$B:$B,"="&H$1,Waivers!$F:$F,">"&datevalue($B16-1),Waivers!$F:$F,"<"&datevalue($B20+1),Waivers!$G:$G,">9")) -> 2 | I19: =IF(countifs(Waivers!$B:$B,"="&I$1,Waivers!$F:$F,">"&datevalue($B16-1),Waivers!$F:$F,"<"&datevalue($B20+1),Waivers!$G:$G,">9")>4,5,countifs(Waivers!$B:$B,"="&I$1,Waivers!$F:$F,">"&datevalue($B16-1),Waivers!$F:$F,"<"&datevalue($B20+1),Waivers!$G:$G,">9")) -> 0 | J19: =IF(countifs(Waivers!$B:$B,"="&J$1,Waivers!$F:$F,">"&datevalue($B16-1),Waivers!$F:$F,"<"&datevalue($B20+1),Waivers!$G:$G,">9")>4,5,countifs(Waivers!$B:$B,"="&J$1,Waivers!$F:$F,">"&datevalue($B16-1),Waivers!$F:$F,"<"&datevalue($B20+1),Waivers!$G:$G,">9")) -> 0 | K19: =IF(countifs(Waivers!$B:$B,"="&K$1,Waivers!$F:$F,">"&datevalue($B16-1),Waivers!$F:$F,"<"&datevalue($B20+1),Waivers!$G:$G,">9")>4,5,countifs(Waivers!$B:$B,"="&K$1,Waivers!$F:$F,">"&datevalue($B16-1),Waivers!$F:$F,"<"&datevalue($B20+1),Waivers!$G:$G,">9")) -> 1 | ... O19: =IF(countifs(Waivers!$B:$B,"="&O$1,Waivers!$F:$F,">"&datevalue($B16-1),Waivers!$F:$F,"<"&datevalue($B20+1),Waivers!$G:$G,">9")>4,5,countifs(Waivers!$B:$B,"="&O$1,Waivers!$F:$F,">"&datevalue($B16-1),Waivers!$F:$F,"<"&datevalue($B20+1),Waivers!$G:$G,">9")) -> 0
B20: 46321 | C20: Promotion Award
A21: Q3 Reg | B21: 46322 | C21: Trades | D21: =IFERROR(__xludf.DUMMYFUNCTION("IFNA(filter(Trades!$J:$J,Trades!$B:$B=D$1,Trades!$A:$A>=$B21,Trades!$A:$A<=$B24),0)+IFNA(filter(Trades!$J:$J,Trades!$F:$F=D$1,Trades!$A:$A>=$B21,Trades!$A:$A<=$B24),0)"),0.0) -> 0 | E21: =IFERROR(__xludf.DUMMYFUNCTION("IFNA(filter(Trades!$J:$J,Trades!$B:$B=E$1,Trades!$A:$A>=$B21,Trades!$A:$A<=$B23),0)+IFNA(filter(Trades!$J:$J,Trades!$F:$F=E$1,Trades!$A:$A>=$B21,Trades!$A:$A<=$B23),0)"),0.0) -> 0 | F21: =IFERROR(__xludf.DUMMYFUNCTION("IFNA(filter(Trades!$J:$J,Trades!$B:$B=F$1,Trades!$A:$A>=$B21,Trades!$A:$A<=$B23),0)+IFNA(filter(Trades!$J:$J,Trades!$F:$F=F$1,Trades!$A:$A>=$B21,Trades!$A:$A<=$B23),0)"),0.0) -> 0 | G21: =IFERROR(__xludf.DUMMYFUNCTION("IFNA(filter(Trades!$J:$J,Trades!$B:$B=G$1,Trades!$A:$A>=$B21,Trades!$A:$A<=$B23),0)+IFNA(filter(Trades!$J:$J,Trades!$F:$F=G$1,Trades!$A:$A>=$B21,Trades!$A:$A<=$B23),0)"),0.0) -> 0 | H21: =IFERROR(__xludf.DUMMYFUNCTION("IFNA(filter(Trades!$J:$J,Trades!$B:$B=H$1,Trades!$A:$A>=$B21,Trades!$A:$A<=$B23),0)+IFNA(filter(Trades!$J:$J,Trades!$F:$F=H$1,Trades!$A:$A>=$B21,Trades!$A:$A<=$B23),0)"),0.0) -> 0 | I21: =IFERROR(__xludf.DUMMYFUNCTION("IFNA(filter(Trades!$J:$J,Trades!$B:$B=I$1,Trades!$A:$A>=$B21,Trades!$A:$A<=$B23),0)+IFNA(filter(Trades!$J:$J,Trades!$F:$F=I$1,Trades!$A:$A>=$B21,Trades!$A:$A<=$B23),0)"),0.0) -> 0 | J21: =IFERROR(__xludf.DUMMYFUNCTION("IFNA(filter(Trades!$J:$J,Trades!$B:$B=J$1,Trades!$A:$A>=$B21,Trades!$A:$A<=$B23),0)+IFNA(filter(Trades!$J:$J,Trades!$F:$F=J$1,Trades!$A:$A>=$B21,Trades!$A:$A<=$B23),0)"),0.0) -> 0 | K21: =IFERROR(__xludf.DUMMYFUNCTION("IFNA(filter(Trades!$J:$J,Trades!$B:$B=K$1,Trades!$A:$A>=$B21,Trades!$A:$A<=$B23),0)+IFNA(filter(Trades!$J:$J,Trades!$F:$F=K$1,Trades!$A:$A>=$B21,Trades!$A:$A<=$B23),0)"),0.0) -> 0 | L21: =IFERROR(__xludf.DUMMYFUNCTION("IFNA(filter(Trades!$J:$J,Trades!$B:$B=L$1,Trades!$A:$A>=$B21,Trades!$A:$A<=$B23),0)+IFNA(filter(Trades!$J:$J,Trades!$F:$F=L$1,Trades!$A:$A>=$B21,Trades!$A:$A<=$B23),0)"),0.0) -> 0 | M21: =IFERROR(__xludf.DUMMYFUNCTION("IFNA(filter(Trades!$J:$J,Trades!$B:$B=M$1,Trades!$A:$A>=$B21,Trades!$A:$A<=$B23),0)+IFNA(filter(Trades!$J:$J,Trades!$F:$F=M$1,Trades!$A:$A>=$B21,Trades!$A:$A<=$B23),0)"),0.0) -> 0 | N21: =IFERROR(__xludf.DUMMYFUNCTION("IFNA(filter(Trades!$J:$J,Trades!$B:$B=N$1,Trades!$A:$A>=$B21,Trades!$A:$A<=$B23),0)+IFNA(filter(Trades!$J:$J,Trades!$F:$F=N$1,Trades!$A:$A>=$B21,Trades!$A:$A<=$B23),0)"),0.0) -> 0 | O21: =IFERROR(__xludf.DUMMYFUNCTION("IFNA(filter(Trades!$J:$J,Trades!$B:$B=O$1,Trades!$A:$A>=$B21,Trades!$A:$A<=$B23),0)+IFNA(filter(Trades!$J:$J,Trades!$F:$F=O$1,Trades!$A:$A>=$B21,Trades!$A:$A<=$B23),0)"),0.0) -> 0
C22: Tokens Traded/Voided
C23: Adds >= $25 | D23: =IF(countifs(Waivers!$B:$B,"="&D$1,Waivers!$F:$F,">"&datevalue($B20-1),Waivers!$F:$F,"<"&datevalue($B24+1),Waivers!$G:$G,">9")>4,5,countifs(Waivers!$B:$B,"="&D$1,Waivers!$F:$F,">"&datevalue($B20-1),Waivers!$F:$F,"<"&datevalue($B24+1),Waivers!$G:$G,">9")) -> 0 | E23: =IF(countifs(Waivers!$B:$B,"="&E$1,Waivers!$F:$F,">"&datevalue($B20-1),Waivers!$F:$F,"<"&datevalue($B24+1),Waivers!$G:$G,">9")>4,5,countifs(Waivers!$B:$B,"="&E$1,Waivers!$F:$F,">"&datevalue($B20-1),Waivers!$F:$F,"<"&datevalue($B24+1),Waivers!$G:$G,">9")) -> 0 | F23: =IF(countifs(Waivers!$B:$B,"="&F$1,Waivers!$F:$F,">"&datevalue($B20-1),Waivers!$F:$F,"<"&datevalue($B24+1),Waivers!$G:$G,">9")>4,5,countifs(Waivers!$B:$B,"="&F$1,Waivers!$F:$F,">"&datevalue($B20-1),Waivers!$F:$F,"<"&datevalue($B24+1),Waivers!$G:$G,">9")) -> 0 | G23: =IF(countifs(Waivers!$B:$B,"="&G$1,Waivers!$F:$F,">"&datevalue($B20-1),Waivers!$F:$F,"<"&datevalue($B24+1),Waivers!$G:$G,">9")>4,5,countifs(Waivers!$B:$B,"="&G$1,Waivers!$F:$F,">"&datevalue($B20-1),Waivers!$F:$F,"<"&datevalue($B24+1),Waivers!$G:$G,">9")) -> 0 | H23: =IF(countifs(Waivers!$B:$B,"="&H$1,Waivers!$F:$F,">"&datevalue($B20-1),Waivers!$F:$F,"<"&datevalue($B24+1),Waivers!$G:$G,">9")>4,5,countifs(Waivers!$B:$B,"="&H$1,Waivers!$F:$F,">"&datevalue($B20-1),Waivers!$F:$F,"<"&datevalue($B24+1),Waivers!$G:$G,">9")) -> 0 | I23: =IF(countifs(Waivers!$B:$B,"="&I$1,Waivers!$F:$F,">"&datevalue($B20-1),Waivers!$F:$F,"<"&datevalue($B24+1),Waivers!$G:$G,">9")>4,5,countifs(Waivers!$B:$B,"="&I$1,Waivers!$F:$F,">"&datevalue($B20-1),Waivers!$F:$F,"<"&datevalue($B24+1),Waivers!$G:$G,">9")) -> 0 | J23: =IF(countifs(Waivers!$B:$B,"="&J$1,Waivers!$F:$F,">"&datevalue($B20-1),Waivers!$F:$F,"<"&datevalue($B24+1),Waivers!$G:$G,">9")>4,5,countifs(Waivers!$B:$B,"="&J$1,Waivers!$F:$F,">"&datevalue($B20-1),Waivers!$F:$F,"<"&datevalue($B24+1),Waivers!$G:$G,">9")) -> 0 | K23: =IF(countifs(Waivers!$B:$B,"="&K$1,Waivers!$F:$F,">"&datevalue($B20-1),Waivers!$F:$F,"<"&datevalue($B24+1),Waivers!$G:$G,">9")>4,5,countifs(Waivers!$B:$B,"="&K$1,Waivers!$F:$F,">"&datevalue($B20-1),Waivers!$F:$F,"<"&datevalue($B24+1),Waivers!$G:$G,">9")) -> 0 | ... O23: =IF(countifs(Waivers!$B:$B,"="&O$1,Waivers!$F:$F,">"&datevalue($B20-1),Waivers!$F:$F,"<"&datevalue($B24+1),Waivers!$G:$G,">9")>4,5,countifs(Waivers!$B:$B,"="&O$1,Waivers!$F:$F,">"&datevalue($B20-1),Waivers!$F:$F,"<"&datevalue($B24+1),Waivers!$G:$G,">9")) -> 0
B24: 46349 | C24: Promotion Award
A25: Post | B25: 46350 | C25: Trades | D25: =IFERROR(__xludf.DUMMYFUNCTION("IFNA(filter(Trades!$J:$J,Trades!$B:$B=D$1,Trades!$A:$A>=$B25,Trades!$A:$A<=$B27),0)+IFNA(filter(Trades!$J:$J,Trades!$F:$F=D$1,Trades!$A:$A>=$B25,Trades!$A:$A<=$B27),0)"),0.0) -> 0 | E25: =IFERROR(__xludf.DUMMYFUNCTION("IFNA(filter(Trades!$J:$J,Trades!$B:$B=E$1,Trades!$A:$A>=$B25,Trades!$A:$A<=$B27),0)+IFNA(filter(Trades!$J:$J,Trades!$F:$F=E$1,Trades!$A:$A>=$B25,Trades!$A:$A<=$B27),0)"),0.0) -> 0 | F25: =IFERROR(__xludf.DUMMYFUNCTION("IFNA(filter(Trades!$J:$J,Trades!$B:$B=F$1,Trades!$A:$A>=$B25,Trades!$A:$A<=$B27),0)+IFNA(filter(Trades!$J:$J,Trades!$F:$F=F$1,Trades!$A:$A>=$B25,Trades!$A:$A<=$B27),0)"),0.0) -> 0 | G25: =IFERROR(__xludf.DUMMYFUNCTION("IFNA(filter(Trades!$J:$J,Trades!$B:$B=G$1,Trades!$A:$A>=$B25,Trades!$A:$A<=$B27),0)+IFNA(filter(Trades!$J:$J,Trades!$F:$F=G$1,Trades!$A:$A>=$B25,Trades!$A:$A<=$B27),0)"),0.0) -> 0 | H25: =IFERROR(__xludf.DUMMYFUNCTION("IFNA(filter(Trades!$J:$J,Trades!$B:$B=H$1,Trades!$A:$A>=$B25,Trades!$A:$A<=$B27),0)+IFNA(filter(Trades!$J:$J,Trades!$F:$F=H$1,Trades!$A:$A>=$B25,Trades!$A:$A<=$B27),0)"),0.0) -> 0 | I25: =IFERROR(__xludf.DUMMYFUNCTION("IFNA(filter(Trades!$J:$J,Trades!$B:$B=I$1,Trades!$A:$A>=$B25,Trades!$A:$A<=$B27),0)+IFNA(filter(Trades!$J:$J,Trades!$F:$F=I$1,Trades!$A:$A>=$B25,Trades!$A:$A<=$B27),0)"),0.0) -> 0 | J25: =IFERROR(__xludf.DUMMYFUNCTION("IFNA(filter(Trades!$J:$J,Trades!$B:$B=J$1,Trades!$A:$A>=$B25,Trades!$A:$A<=$B27),0)+IFNA(filter(Trades!$J:$J,Trades!$F:$F=J$1,Trades!$A:$A>=$B25,Trades!$A:$A<=$B27),0)"),0.0) -> 0 | K25: =IFERROR(__xludf.DUMMYFUNCTION("IFNA(filter(Trades!$J:$J,Trades!$B:$B=K$1,Trades!$A:$A>=$B25,Trades!$A:$A<=$B27),0)+IFNA(filter(Trades!$J:$J,Trades!$F:$F=K$1,Trades!$A:$A>=$B25,Trades!$A:$A<=$B27),0)"),0.0) -> 0 | L25: =IFERROR(__xludf.DUMMYFUNCTION("IFNA(filter(Trades!$J:$J,Trades!$B:$B=L$1,Trades!$A:$A>=$B25,Trades!$A:$A<=$B27),0)+IFNA(filter(Trades!$J:$J,Trades!$F:$F=L$1,Trades!$A:$A>=$B25,Trades!$A:$A<=$B27),0)"),0.0) -> 0 | M25: =IFERROR(__xludf.DUMMYFUNCTION("IFNA(filter(Trades!$J:$J,Trades!$B:$B=M$1,Trades!$A:$A>=$B25,Trades!$A:$A<=$B27),0)+IFNA(filter(Trades!$J:$J,Trades!$F:$F=M$1,Trades!$A:$A>=$B25,Trades!$A:$A<=$B27),0)"),0.0) -> 0 | N25: =IFERROR(__xludf.DUMMYFUNCTION("IFNA(filter(Trades!$J:$J,Trades!$B:$B=N$1,Trades!$A:$A>=$B25,Trades!$A:$A<=$B27),0)+IFNA(filter(Trades!$J:$J,Trades!$F:$F=N$1,Trades!$A:$A>=$B25,Trades!$A:$A<=$B27),0)"),0.0) -> 0 | O25: =IFERROR(__xludf.DUMMYFUNCTION("IFNA(filter(Trades!$J:$J,Trades!$B:$B=O$1,Trades!$A:$A>=$B25,Trades!$A:$A<=$B27),0)+IFNA(filter(Trades!$J:$J,Trades!$F:$F=O$1,Trades!$A:$A>=$B25,Trades!$A:$A<=$B27),0)"),0.0) -> 0
A26: Season | C26: Tokens Traded
B27: 46387 | C27: Adds >= $25 | D27: =IF(countifs(Waivers!$B:$B,"="&D$1,Waivers!$F:$F,">"&datevalue($B25-1),Waivers!$F:$F,"<"&datevalue($B27+1),Waivers!$G:$G,">9")>4,5,countifs(Waivers!$B:$B,"="&D$1,Waivers!$F:$F,">"&datevalue($B25-1),Waivers!$F:$F,"<"&datevalue($B27+1),Waivers!$G:$G,">9")) -> 0 | E27: =IF(countifs(Waivers!$B:$B,"="&E$1,Waivers!$F:$F,">"&datevalue($B25-1),Waivers!$F:$F,"<"&datevalue($B27+1),Waivers!$G:$G,">9")>4,5,countifs(Waivers!$B:$B,"="&E$1,Waivers!$F:$F,">"&datevalue($B25-1),Waivers!$F:$F,"<"&datevalue($B27+1),Waivers!$G:$G,">9")) -> 0 | F27: =IF(countifs(Waivers!$B:$B,"="&F$1,Waivers!$F:$F,">"&datevalue($B25-1),Waivers!$F:$F,"<"&datevalue($B27+1),Waivers!$G:$G,">9")>4,5,countifs(Waivers!$B:$B,"="&F$1,Waivers!$F:$F,">"&datevalue($B25-1),Waivers!$F:$F,"<"&datevalue($B27+1),Waivers!$G:$G,">9")) -> 0 | G27: =IF(countifs(Waivers!$B:$B,"="&G$1,Waivers!$F:$F,">"&datevalue($B25-1),Waivers!$F:$F,"<"&datevalue($B27+1),Waivers!$G:$G,">9")>4,5,countifs(Waivers!$B:$B,"="&G$1,Waivers!$F:$F,">"&datevalue($B25-1),Waivers!$F:$F,"<"&datevalue($B27+1),Waivers!$G:$G,">9")) -> 0 | H27: =IF(countifs(Waivers!$B:$B,"="&H$1,Waivers!$F:$F,">"&datevalue($B25-1),Waivers!$F:$F,"<"&datevalue($B27+1),Waivers!$G:$G,">9")>4,5,countifs(Waivers!$B:$B,"="&H$1,Waivers!$F:$F,">"&datevalue($B25-1),Waivers!$F:$F,"<"&datevalue($B27+1),Waivers!$G:$G,">9")) -> 0 | I27: =IF(countifs(Waivers!$B:$B,"="&I$1,Waivers!$F:$F,">"&datevalue($B25-1),Waivers!$F:$F,"<"&datevalue($B27+1),Waivers!$G:$G,">9")>4,5,countifs(Waivers!$B:$B,"="&I$1,Waivers!$F:$F,">"&datevalue($B25-1),Waivers!$F:$F,"<"&datevalue($B27+1),Waivers!$G:$G,">9")) -> 0 | J27: =IF(countifs(Waivers!$B:$B,"="&J$1,Waivers!$F:$F,">"&datevalue($B25-1),Waivers!$F:$F,"<"&datevalue($B27+1),Waivers!$G:$G,">9")>4,5,countifs(Waivers!$B:$B,"="&J$1,Waivers!$F:$F,">"&datevalue($B25-1),Waivers!$F:$F,"<"&datevalue($B27+1),Waivers!$G:$G,">9")) -> 0 | K27: =IF(countifs(Waivers!$B:$B,"="&K$1,Waivers!$F:$F,">"&datevalue($B25-1),Waivers!$F:$F,"<"&datevalue($B27+1),Waivers!$G:$G,">9")>4,5,countifs(Waivers!$B:$B,"="&K$1,Waivers!$F:$F,">"&datevalue($B25-1),Waivers!$F:$F,"<"&datevalue($B27+1),Waivers!$G:$G,">9")) -> 0 | ... O27: =IF(countifs(Waivers!$B:$B,"="&O$1,Waivers!$F:$F,">"&datevalue($B25-1),Waivers!$F:$F,"<"&datevalue($B27+1),Waivers!$G:$G,">9")>4,5,countifs(Waivers!$B:$B,"="&O$1,Waivers!$F:$F,">"&datevalue($B25-1),Waivers!$F:$F,"<"&datevalue($B27+1),Waivers!$G:$G,">9")) -> 0
A28: Token Award Draw | B28: 46395 | C28: Tokens Committed
A29: Token Award Draw | B29: 46397 | C29: Tokens Won

Sheet Trades

Sheet Waivers
A1: Date | B1: Team | C1: Add | D1: Amount | E1: 371
A2: =IFERROR(__xludf.DUMMYFUNCTION("importhtml(""https://www.myfantasyleague.com/2026/options?L=63213&O=03&TYPE=WAIVER&FRANCHISE=0000&DAYS=3000&REFRESH=""&E1,""table"",2)"),"#") -> # | B2: =IFERROR(__xludf.DUMMYFUNCTION("""COMPUTED_VALUE"""),"Franchise") -> Franchise | C2: =IFERROR(__xludf.DUMMYFUNCTION("""COMPUTED_VALUE"""),"Type") -> Type | D2: =IFERROR(__xludf.DUMMYFUNCTION("""COMPUTED_VALUE"""),"Transaction") -> Transaction | E2: =IFERROR(__xludf.DUMMYFUNCTION("""COMPUTED_VALUE"""),"Date") -> Date | F2: Date | G2: Value | H2: Voided
A3: =IFERROR(__xludf.DUMMYFUNCTION("""COMPUTED_VALUE"""),1.0) -> 1 | B3: =IFERROR(__xludf.DUMMYFUNCTION("""COMPUTED_VALUE"""),"BattleBots") -> BattleBots | C3: =IFERROR(__xludf.DUMMYFUNCTION("""COMPUTED_VALUE"""),"Waiver") -> Waiver | D3: =IFERROR(__xludf.DUMMYFUNCTION("""COMPUTED_VALUE"""),"- Acquired Tremble, Tommy CAR TE for $1.00") -> - Acquired Tremble, Tommy CAR TE for $1.00 | E3: =IFERROR(__xludf.DUMMYFUNCTION("""COMPUTED_VALUE"""),"Wed Oct 21 11:00:00 a.m. ET 2026") -> Wed Oct 21 11:00:00 a.m. ET 2026 | F3: =iferror(datevalue(left(E3,10)&right(E3,5)),"") -> 46316 | G3: =iferror(value(mid(D3,find("$",D3)+1,4)),"") -> 1
A4: =IFERROR(__xludf.DUMMYFUNCTION("""COMPUTED_VALUE"""),2.0) -> 2 | B4: =IFERROR(__xludf.DUMMYFUNCTION("""COMPUTED_VALUE"""),"Orcan Terror") -> Orcan Terror | C4: =IFERROR(__xludf.DUMMYFUNCTION("""COMPUTED_VALUE"""),"Waiver") -> Waiver | D4: =IFERROR(__xludf.DUMMYFUNCTION("""COMPUTED_VALUE"""),"- Acquired Cooks, Brandin SFO WR for $25.00 - Dropped Cooper, Darius PHI WR") -> - Acquired Cooks, Brandin SFO WR for $25.00 - Dropped Cooper, Darius PHI WR | E4: =IFERROR(__xludf.DUMMYFUNCTION("""COMPUTED_VALUE"""),"Wed Oct 21 11:00:00 a.m. ET 2026") -> Wed Oct 21 11:00:00 a.m. ET 2026 | F4: =iferror(datevalue(left(E4,10)&right(E4,5)),"") -> 46316 | G4: =iferror(value(mid(D4,find("$",D4)+1,4)),"") -> 25
A5: =IFERROR(__xludf.DUMMYFUNCTION("""COMPUTED_VALUE"""),3.0) -> 3 | B5: =IFERROR(__xludf.DUMMYFUNCTION("""COMPUTED_VALUE"""),"Springfield Isotopes") -> Springfield Isotopes | C5: =IFERROR(__xludf.DUMMYFUNCTION("""COMPUTED_VALUE"""),"Waiver") -> Waiver | D5: =IFERROR(__xludf.DUMMYFUNCTION("""COMPUTED_VALUE"""),"- Acquired Mumpfield, Konata LAR WR for $37.00 - Dropped Patrick, Tim NYJ WR") -> - Acquired Mumpfield, Konata LAR WR for $37.00 - Dropped Patrick, Tim NYJ WR | E5: =IFERROR(__xludf.DUMMYFUNCTION("""COMPUTED_VALUE"""),"Wed Oct 21 11:00:00 a.m. ET 2026") -> Wed Oct 21 11:00:00 a.m. ET 2026 | F5: =iferror(datevalue(left(E5,10)&right(E5,5)),"") -> 46316 | G5: =iferror(value(mid(D5,find("$",D5)+1,4)),"") -> 37
A6: =IFERROR(__xludf.DUMMYFUNCTION("""COMPUTED_VALUE"""),4.0) -> 4 | B6: =IFERROR(__xludf.DUMMYFUNCTION("""COMPUTED_VALUE"""),"BattleBots") -> BattleBots | C6: =IFERROR(__xludf.DUMMYFUNCTION("""COMPUTED_VALUE"""),"Waiver") -> Waiver | D6: =IFERROR(__xludf.DUMMYFUNCTION("""COMPUTED_VALUE"""),"- Acquired Johnson, Roschon CHI RB for $51.00") -> - Acquired Johnson, Roschon CHI RB for $51.00 | E6: =IFERROR(__xludf.DUMMYFUNCTION("""COMPUTED_VALUE"""),"Wed Oct 21 11:00:00 a.m. ET 2026") -> Wed Oct 21 11:00:00 a.m. ET 2026 | F6: =iferror(datevalue(left(E6,10)&right(E6,5)),"") -> 46316 | G6: =iferror(value(mid(D6,find("$",D6)+1,4)),"") -> 51
A7: =IFERROR(__xludf.DUMMYFUNCTION("""COMPUTED_VALUE"""),5.0) -> 5 | B7: =IFERROR(__xludf.DUMMYFUNCTION("""COMPUTED_VALUE"""),"BattleBots") -> BattleBots | C7: =IFERROR(__xludf.DUMMYFUNCTION("""COMPUTED_VALUE"""),"Waiver") -> Waiver | D7: =IFERROR(__xludf.DUMMYFUNCTION("""COMPUTED_VALUE"""),"- Acquired Bagent, Tyson CHI QB for $1.00") -> - Acquired Bagent, Tyson CHI QB for $1.00 | E7: =IFERROR(__xludf.DUMMYFUNCTION("""COMPUTED_VALUE"""),"Fri Oct 16 11:00:00 a.m. ET 2026") -> Fri Oct 16 11:00:00 a.m. ET 2026 | F7: =iferror(datevalue(left(E7,10)&right(E7,5)),"") -> 46311 | G7: =iferror(value(mid(D7,find("$",D7)+1,4)),"") -> 1
A8: =IFERROR(__xludf.DUMMYFUNCTION("""COMPUTED_VALUE"""),6.0) -> 6 | B8: =IFERROR(__xludf.DUMMYFUNCTION("""COMPUTED_VALUE"""),"BattleBots") -> BattleBots | C8: =IFERROR(__xludf.DUMMYFUNCTION("""COMPUTED_VALUE"""),"Waiver") -> Waiver | D8: =IFERROR(__xludf.DUMMYFUNCTION("""COMPUTED_VALUE"""),"- Acquired Treadwell, Laquon IND WR for $1.00 - Dropped Keenum, Case CHI QB") -> - Acquired Treadwell, Laquon IND WR for $1.00 - Dropped Keenum, Case CHI QB | E8: =IFERROR(__xludf.DUMMYFUNCTION("""COMPUTED_VALUE"""),"Wed Oct 14 11:00:00 a.m. ET 2026") -> Wed Oct 14 11:00:00 a.m. ET 2026 | F8: =iferror(datevalue(left(E8,10)&right(E8,5)),"") -> 46309 | G8: =iferror(value(mid(D8,find("$",D8)+1,4)),"") -> 1
A9: =IFERROR(__xludf.DUMMYFUNCTION("""COMPUTED_VALUE"""),7.0) -> 7 | B9: =IFERROR(__xludf.DUMMYFUNCTION("""COMPUTED_VALUE"""),"Norsemen") -> Norsemen | C9: =IFERROR(__xludf.DUMMYFUNCTION("""COMPUTED_VALUE"""),"Waiver") -> Waiver | D9: =IFERROR(__xludf.DUMMYFUNCTION("""COMPUTED_VALUE"""),"- Acquired Felton, Tai MIN WR for $1.00 - Dropped Vaki, Sione DET RB") -> - Acquired Felton, Tai MIN WR for $1.00 - Dropped Vaki, Sione DET RB | E9: =IFERROR(__xludf.DUMMYFUNCTION("""COMPUTED_VALUE"""),"Wed Oct 14 11:00:00 a.m. ET 2026") -> Wed Oct 14 11:00:00 a.m. ET 2026 | F9: =iferror(datevalue(left(E9,10)&right(E9,5)),"") -> 46309 | G9: =iferror(value(mid(D9,find("$",D9)+1,4)),"") -> 1
A10: =IFERROR(__xludf.DUMMYFUNCTION("""COMPUTED_VALUE"""),8.0) -> 8 | B10: =IFERROR(__xludf.DUMMYFUNCTION("""COMPUTED_VALUE"""),"Orcan Terror") -> Orcan Terror | C10: =IFERROR(__xludf.DUMMYFUNCTION("""COMPUTED_VALUE"""),"Waiver") -> Waiver | D10: =IFERROR(__xludf.DUMMYFUNCTION("""COMPUTED_VALUE"""),"- Acquired Pierce, Dameon PHI RB for $28.00 - Dropped Rattler, Spencer NOS QB") -> - Acquired Pierce, Dameon PHI RB for $28.00 - Dropped Rattler, Spencer NOS QB | E10: =IFERROR(__xludf.DUMMYFUNCTION("""COMPUTED_VALUE"""),"Wed Oct 14 11:00:00 a.m. ET 2026") -> Wed Oct 14 11:00:00 a.m. ET 2026 | F10: =iferror(datevalue(left(E10,10)&right(E10,5)),"") -> 46309 | G10: =iferror(value(mid(D10,find("$",D10)+1,4)),"") -> 28
A11: =IFERROR(__xludf.DUMMYFUNCTION("""COMPUTED_VALUE"""),9.0) -> 9 | B11: =IFERROR(__xludf.DUMMYFUNCTION("""COMPUTED_VALUE"""),"Shankly's Ghost") -> Shankly's Ghost | C11: =IFERROR(__xludf.DUMMYFUNCTION("""COMPUTED_VALUE"""),"Waiver") -> Waiver | D11: =IFERROR(__xludf.DUMMYFUNCTION("""COMPUTED_VALUE"""),"- Acquired Ayomanor, Elic TEN WR for $3.00 - Dropped Allen, Kaytron MIA RB") -> - Acquired Ayomanor, Elic TEN WR for $3.00 - Dropped Allen, Kaytron MIA RB | E11: =IFERROR(__xludf.DUMMYFUNCTION("""COMPUTED_VALUE"""),"Fri Oct 9 11:00:00 a.m. ET 2026") -> Fri Oct 9 11:00:00 a.m. ET 2026 | F11: =iferror(datevalue(left(E11,10)&right(E11,5)),"") -> 46304 | G11: =iferror(value(mid(D11,find("$",D11)+1,4)),"") -> 3
A12: =IFERROR(__xludf.DUMMYFUNCTION("""COMPUTED_VALUE"""),10.0) -> 10 | B12: =IFERROR(__xludf.DUMMYFUNCTION("""COMPUTED_VALUE"""),"Springfield Isotopes") -> Springfield Isotopes | C12: =IFERROR(__xludf.DUMMYFUNCTION("""COMPUTED_VALUE"""),"Waiver") -> Waiver | D12: =IFERROR(__xludf.DUMMYFUNCTION("""COMPUTED_VALUE"""),"- Acquired Vidal, Kimani LAC RB for $2.00 - Dropped Ridley, Calvin TEN WR") -> - Acquired Vidal, Kimani LAC RB for $2.00 - Dropped Ridley, Calvin TEN WR | E12: =IFERROR(__xludf.DUMMYFUNCTION("""COMPUTED_VALUE"""),"Wed Oct 7 11:00:00 a.m. ET 2026") -> Wed Oct 7 11:00:00 a.m. ET 2026 | F12: =iferror(datevalue(left(E12,10)&right(E12,5)),"") -> 46302 | G12: =iferror(value(mid(D12,find("$",D12)+1,4)),"") -> 2
A13: =IFERROR(__xludf.DUMMYFUNCTION("""COMPUTED_VALUE"""),11.0) -> 11 | B13: =IFERROR(__xludf.DUMMYFUNCTION("""COMPUTED_VALUE"""),"BattleBots") -> BattleBots | C13: =IFERROR(__xludf.DUMMYFUNCTION("""COMPUTED_VALUE"""),"Waiver") -> Waiver | D13: =IFERROR(__xludf.DUMMYFUNCTION("""COMPUTED_VALUE"""),"- Acquired Royals, Jalen KCC WR for $25.00 - Dropped Davis, Ray BUF RB") -> - Acquired Royals, Jalen KCC WR for $25.00 - Dropped Davis, Ray BUF RB | E13: =IFERROR(__xludf.DUMMYFUNCTION("""COMPUTED_VALUE"""),"Wed Oct 7 11:00:00 a.m. ET 2026") -> Wed Oct 7 11:00:00 a.m. ET 2026 | F13: =iferror(datevalue(left(E13,10)&right(E13,5)),"") -> 46302 | G13: =iferror(value(mid(D13,find("$",D13)+1,4)),"") -> 25
A14: =IFERROR(__xludf.DUMMYFUNCTION("""COMPUTED_VALUE"""),12.0) -> 12 | B14: =IFERROR(__xludf.DUMMYFUNCTION("""COMPUTED_VALUE"""),"The Two Tones") -> The Two Tones | C14: =IFERROR(__xludf.DUMMYFUNCTION("""COMPUTED_VALUE"""),"Waiver") -> Waiver | D14: =IFERROR(__xludf.DUMMYFUNCTION("""COMPUTED_VALUE"""),"- Acquired Meyers, Dohnte CIN WR for $45.00 - Dropped Horn, Jimmy CLE WR") -> - Acquired Meyers, Dohnte CIN WR for $45.00 - Dropped Horn, Jimmy CLE WR | E14: =IFERROR(__xludf.DUMMYFUNCTION("""COMPUTED_VALUE"""),"Wed Oct 7 11:00:00 a.m. ET 2026") -> Wed Oct 7 11:00:00 a.m. ET 2026 | F14: =iferror(datevalue(left(E14,10)&right(E14,5)),"") -> 46302 | G14: =iferror(value(mid(D14,find("$",D14)+1,4)),"") -> 45
A15: =IFERROR(__xludf.DUMMYFUNCTION("""COMPUTED_VALUE"""),13.0) -> 13 | B15: =IFERROR(__xludf.DUMMYFUNCTION("""COMPUTED_VALUE"""),"BattleBots") -> BattleBots | C15: =IFERROR(__xludf.DUMMYFUNCTION("""COMPUTED_VALUE"""),"Waiver") -> Waiver | D15: =IFERROR(__xludf.DUMMYFUNCTION("""COMPUTED_VALUE"""),"- Acquired Johnson, Roschon CHI RB for $25.00 - Dropped Tremble, Tommy CAR TE") -> - Acquired Johnson, Roschon CHI RB for $25.00 - Dropped Tremble, Tommy CAR TE | E15: =IFERROR(__xludf.DUMMYFUNCTION("""COMPUTED_VALUE"""),"Fri Oct 2 11:00:00 a.m. ET 2026") -> Fri Oct 2 11:00:00 a.m. ET 2026 | F15: =iferror(datevalue(left(E15,10)&right(E15,5)),"") -> 46297 | G15: =iferror(value(mid(D15,find("$",D15)+1,4)),"") -> 25
A16: =IFERROR(__xludf.DUMMYFUNCTION("""COMPUTED_VALUE"""),14.0) -> 14 | B16: =IFERROR(__xludf.DUMMYFUNCTION("""COMPUTED_VALUE"""),"Peaky Fookin Blinders") -> Peaky Fookin Blinders | C16: =IFERROR(__xludf.DUMMYFUNCTION("""COMPUTED_VALUE"""),"Waiver") -> Waiver | D16: =IFERROR(__xludf.DUMMYFUNCTION("""COMPUTED_VALUE"""),"- Acquired Mumpfield, Konata LAR WR for $71.00 - Dropped Walker, Jahdae CHI WR") -> - Acquired Mumpfield, Konata LAR WR for $71.00 - Dropped Walker, Jahdae CHI WR | E16: =IFERROR(__xludf.DUMMYFUNCTION("""COMPUTED_VALUE"""),"Wed Sep 30 11:00:00 a.m. ET 2026") -> Wed Sep 30 11:00:00 a.m. ET 2026 | F16: =iferror(datevalue(left(E16,10)&right(E16,5)),"") -> 46295 | G16: =iferror(value(mid(D16,find("$",D16)+1,4)),"") -> 71
A17: =IFERROR(__xludf.DUMMYFUNCTION("""COMPUTED_VALUE"""),15.0) -> 15 | B17: =IFERROR(__xludf.DUMMYFUNCTION("""COMPUTED_VALUE"""),"Orcan Terror") -> Orcan Terror | C17: =IFERROR(__xludf.DUMMYFUNCTION("""COMPUTED_VALUE"""),"Waiver") -> Waiver | D17: =IFERROR(__xludf.DUMMYFUNCTION("""COMPUTED_VALUE"""),"- Acquired Wayne, Jared MIA WR for $0.00 - Dropped Metchie, John CAR WR") -> - Acquired Wayne, Jared MIA WR for $0.00 - Dropped Metchie, John CAR WR | E17: =IFERROR(__xludf.DUMMYFUNCTION("""COMPUTED_VALUE"""),"Fri Sep 25 11:00:00 a.m. ET 2026") -> Fri Sep 25 11:00:00 a.m. ET 2026 | F17: =iferror(datevalue(left(E17,10)&right(E17,5)),"") -> 46290 | G17: =iferror(value(mid(D17,find("$",D17)+1,4)),"") -> 0
A18: =IFERROR(__xludf.DUMMYFUNCTION("""COMPUTED_VALUE"""),16.0) -> 16 | B18: =IFERROR(__xludf.DUMMYFUNCTION("""COMPUTED_VALUE"""),"Ted Lasso") -> Ted Lasso | C18: =IFERROR(__xludf.DUMMYFUNCTION("""COMPUTED_VALUE"""),"Waiver") -> Waiver | D18: =IFERROR(__xludf.DUMMYFUNCTION("""COMPUTED_VALUE"""),"- Acquired Knox, Dawson BUF TE for $0.00") -> - Acquired Knox, Dawson BUF TE for $0.00 | E18: =IFERROR(__xludf.DUMMYFUNCTION("""COMPUTED_VALUE"""),"Wed Sep 23 11:00:00 a.m. ET 2026") -> Wed Sep 23 11:00:00 a.m. ET 2026 | F18: =iferror(datevalue(left(E18,10)&right(E18,5)),"") -> 46288 | G18: =iferror(value(mid(D18,find("$",D18)+1,4)),"") -> 0
A19: =IFERROR(__xludf.DUMMYFUNCTION("""COMPUTED_VALUE"""),17.0) -> 17 | B19: =IFERROR(__xludf.DUMMYFUNCTION("""COMPUTED_VALUE"""),"Springfield Isotopes") -> Springfield Isotopes | C19: =IFERROR(__xludf.DUMMYFUNCTION("""COMPUTED_VALUE"""),"Waiver") -> Waiver | D19: =IFERROR(__xludf.DUMMYFUNCTION("""COMPUTED_VALUE"""),"- Acquired Winston, Jameis NYG QB for $4.00 - Dropped Demercado, Emari DAL RB") -> - Acquired Winston, Jameis NYG QB for $4.00 - Dropped Demercado, Emari DAL RB | E19: =IFERROR(__xludf.DUMMYFUNCTION("""COMPUTED_VALUE"""),"Wed Sep 23 11:00:00 a.m. ET 2026") -> Wed Sep 23 11:00:00 a.m. ET 2026 | F19: =iferror(datevalue(left(E19,10)&right(E19,5)),"") -> 46288 | G19: =iferror(value(mid(D19,find("$",D19)+1,4)),"") -> 4
A20: =IFERROR(__xludf.DUMMYFUNCTION("""COMPUTED_VALUE"""),18.0) -> 18 | B20: =IFERROR(__xludf.DUMMYFUNCTION("""COMPUTED_VALUE"""),"Shankly's Ghost") -> Shankly's Ghost | C20: =IFERROR(__xludf.DUMMYFUNCTION("""COMPUTED_VALUE"""),"Waiver") -> Waiver | D20: =IFERROR(__xludf.DUMMYFUNCTION("""COMPUTED_VALUE"""),"- Acquired Ertz, Zach PHI TE for $21.00 - Dropped Dotson, Jahan ATL WR") -> - Acquired Ertz, Zach PHI TE for $21.00 - Dropped Dotson, Jahan ATL WR | E20: =IFERROR(__xludf.DUMMYFUNCTION("""COMPUTED_VALUE"""),"Wed Sep 23 11:00:00 a.m. ET 2026") -> Wed Sep 23 11:00:00 a.m. ET 2026 | F20: =iferror(datevalue(left(E20,10)&right(E20,5)),"") -> 46288 | G20: =iferror(value(mid(D20,find("$",D20)+1,4)),"") -> 21
A21: =IFERROR(__xludf.DUMMYFUNCTION("""COMPUTED_VALUE"""),19.0) -> 19 | B21: =IFERROR(__xludf.DUMMYFUNCTION("""COMPUTED_VALUE"""),"BattleBots") -> BattleBots | C21: =IFERROR(__xludf.DUMMYFUNCTION("""COMPUTED_VALUE"""),"Waiver") -> Waiver | D21: =IFERROR(__xludf.DUMMYFUNCTION("""COMPUTED_VALUE"""),"- Acquired Keenum, Case CHI QB for $25.00") -> - Acquired Keenum, Case CHI QB for $25.00 | E21: =IFERROR(__xludf.DUMMYFUNCTION("""COMPUTED_VALUE"""),"Wed Sep 23 11:00:00 a.m. ET 2026") -> Wed Sep 23 11:00:00 a.m. ET 2026 | F21: =iferror(datevalue(left(E21,10)&right(E21,5)),"") -> 46288 | G21: =iferror(value(mid(D21,find("$",D21)+1,4)),"") -> 25
A22: =IFERROR(__xludf.DUMMYFUNCTION("""COMPUTED_VALUE"""),20.0) -> 20 | B22: =IFERROR(__xludf.DUMMYFUNCTION("""COMPUTED_VALUE"""),"Peaky Fookin Blinders") -> Peaky Fookin Blinders | C22: =IFERROR(__xludf.DUMMYFUNCTION("""COMPUTED_VALUE"""),"Waiver") -> Waiver | D22: =IFERROR(__xludf.DUMMYFUNCTION("""COMPUTED_VALUE"""),"- Acquired Wilson, Emanuel SEA RB for $323.00 - Dropped Davis, Isaiah NYJ RB") -> - Acquired Wilson, Emanuel SEA RB for $323.00 - Dropped Davis, Isaiah NYJ RB | E22: =IFERROR(__xludf.DUMMYFUNCTION("""COMPUTED_VALUE"""),"Wed Sep 23 11:00:00 a.m. ET 2026") -> Wed Sep 23 11:00:00 a.m. ET 2026 | F22: =iferror(datevalue(left(E22,10)&right(E22,5)),"") -> 46288 | G22: =iferror(value(mid(D22,find("$",D22)+1,4)),"") -> 323
A23: =IFERROR(__xludf.DUMMYFUNCTION("""COMPUTED_VALUE"""),21.0) -> 21 | B23: =IFERROR(__xludf.DUMMYFUNCTION("""COMPUTED_VALUE"""),"Shankly's Ghost") -> Shankly's Ghost | C23: =IFERROR(__xludf.DUMMYFUNCTION("""COMPUTED_VALUE"""),"Waiver") -> Waiver | D23: =IFERROR(__xludf.DUMMYFUNCTION("""COMPUTED_VALUE"""),"- Acquired Wentz, Carson MIN QB for $21.00") -> - Acquired Wentz, Carson MIN QB for $21.00 | E23: =IFERROR(__xludf.DUMMYFUNCTION("""COMPUTED_VALUE"""),"Wed Sep 16 11:00:00 a.m. ET 2026") -> Wed Sep 16 11:00:00 a.m. ET 2026 | F23: =iferror(datevalue(left(E23,10)&right(E23,5)),"") -> 46281 | G23: =iferror(value(mid(D23,find("$",D23)+1,4)),"") -> 21
A24: =IFERROR(__xludf.DUMMYFUNCTION("""COMPUTED_VALUE"""),22.0) -> 22 | B24: =IFERROR(__xludf.DUMMYFUNCTION("""COMPUTED_VALUE"""),"2 Roops, 1 Silva") -> 2 Roops, 1 Silva | C24: =IFERROR(__xludf.DUMMYFUNCTION("""COMPUTED_VALUE"""),"Waiver") -> Waiver | D24: =IFERROR(__xludf.DUMMYFUNCTION("""COMPUTED_VALUE"""),"- Acquired Robinson, Demarcus SFO WR for $25.00") -> - Acquired Robinson, Demarcus SFO WR for $25.00 | E24: =IFERROR(__xludf.DUMMYFUNCTION("""COMPUTED_VALUE"""),"Wed Sep 16 11:00:00 a.m. ET 2026") -> Wed Sep 16 11:00:00 a.m. ET 2026 | F24: =iferror(datevalue(left(E24,10)&right(E24,5)),"") -> 46281 | G24: =iferror(value(mid(D24,find("$",D24)+1,4)),"") -> 25
A25: =IFERROR(__xludf.DUMMYFUNCTION("""COMPUTED_VALUE"""),23.0) -> 23 | B25: =IFERROR(__xludf.DUMMYFUNCTION("""COMPUTED_VALUE"""),"Orcan Terror") -> Orcan Terror | C25: =IFERROR(__xludf.DUMMYFUNCTION("""COMPUTED_VALUE"""),"Waiver") -> Waiver | D25: =IFERROR(__xludf.DUMMYFUNCTION("""COMPUTED_VALUE"""),"- Acquired Bourne, Kendrick ARI WR for $27.00") -> - Acquired Bourne, Kendrick ARI WR for $27.00 | E25: =IFERROR(__xludf.DUMMYFUNCTION("""COMPUTED_VALUE"""),"Wed Sep 16 11:00:00 a.m. ET 2026") -> Wed Sep 16 11:00:00 a.m. ET 2026 | F25: =iferror(datevalue(left(E25,10)&right(E25,5)),"") -> 46281 | G25: =iferror(value(mid(D25,find("$",D25)+1,4)),"") -> 27
A26: =IFERROR(__xludf.DUMMYFUNCTION("""COMPUTED_VALUE"""),24.0) -> 24 | B26: =IFERROR(__xludf.DUMMYFUNCTION("""COMPUTED_VALUE"""),"2 Roops, 1 Silva") -> 2 Roops, 1 Silva | C26: =IFERROR(__xludf.DUMMYFUNCTION("""COMPUTED_VALUE"""),"Waiver") -> Waiver | D26: =IFERROR(__xludf.DUMMYFUNCTION("""COMPUTED_VALUE"""),"- Acquired Raymond, Kalif CHI WR for $50.00") -> - Acquired Raymond, Kalif CHI WR for $50.00 | E26: =IFERROR(__xludf.DUMMYFUNCTION("""COMPUTED_VALUE"""),"Wed Sep 16 11:00:00 a.m. ET 2026") -> Wed Sep 16 11:00:00 a.m. ET 2026 | F26: =iferror(datevalue(left(E26,10)&right(E26,5)),"") -> 46281 | G26: =iferror(value(mid(D26,find("$",D26)+1,4)),"") -> 50
A27: =IFERROR(__xludf.DUMMYFUNCTION("""COMPUTED_VALUE"""),25.0) -> 25 | B27: =IFERROR(__xludf.DUMMYFUNCTION("""COMPUTED_VALUE"""),"2 Roops, 1 Silva") -> 2 Roops, 1 Silva | C27: =IFERROR(__xludf.DUMMYFUNCTION("""COMPUTED_VALUE"""),"Waiver") -> Waiver | D27: =IFERROR(__xludf.DUMMYFUNCTION("""COMPUTED_VALUE"""),"- Acquired Wilson, Roman PIT WR for $70.00 - Dropped Atwell, Tutu LAR WR") -> - Acquired Wilson, Roman PIT WR for $70.00 - Dropped Atwell, Tutu LAR WR | E27: =IFERROR(__xludf.DUMMYFUNCTION("""COMPUTED_VALUE"""),"Wed Sep 16 11:00:00 a.m. ET 2026") -> Wed Sep 16 11:00:00 a.m. ET 2026 | F27: =iferror(datevalue(left(E27,10)&right(E27,5)),"") -> 46281 | G27: =iferror(value(mid(D27,find("$",D27)+1,4)),"") -> 70
A28: =IFERROR(__xludf.DUMMYFUNCTION("""COMPUTED_VALUE"""),26.0) -> 26 | B28: =IFERROR(__xludf.DUMMYFUNCTION("""COMPUTED_VALUE"""),"The Meaty Ogres") -> The Meaty Ogres | C28: =IFERROR(__xludf.DUMMYFUNCTION("""COMPUTED_VALUE"""),"Waiver") -> Waiver | D28: =IFERROR(__xludf.DUMMYFUNCTION("""COMPUTED_VALUE"""),"- Acquired Lock, Drew SEA QB for $107.00") -> - Acquired Lock, Drew SEA QB for $107.00 | E28: =IFERROR(__xludf.DUMMYFUNCTION("""COMPUTED_VALUE"""),"Wed Sep 16 11:00:00 a.m. ET 2026") -> Wed Sep 16 11:00:00 a.m. ET 2026 | F28: =iferror(datevalue(left(E28,10)&right(E28,5)),"") -> 46281 | G28: =iferror(value(mid(D28,find("$",D28)+1,4)),"") -> 107
A29: =IFERROR(__xludf.DUMMYFUNCTION("""COMPUTED_VALUE"""),27.0) -> 27 | B29: =IFERROR(__xludf.DUMMYFUNCTION("""COMPUTED_VALUE"""),"BattleBots") -> BattleBots | C29: =IFERROR(__xludf.DUMMYFUNCTION("""COMPUTED_VALUE"""),"Waiver") -> Waiver | D29: =IFERROR(__xludf.DUMMYFUNCTION("""COMPUTED_VALUE"""),"- Acquired Ayomanor, Elic TEN WR for $1.00") -> - Acquired Ayomanor, Elic TEN WR for $1.00 | E29: =IFERROR(__xludf.DUMMYFUNCTION("""COMPUTED_VALUE"""),"Wed Sep 9 11:00:00 a.m. ET 2026") -> Wed Sep 9 11:00:00 a.m. ET 2026 | F29: =iferror(datevalue(left(E29,10)&right(E29,5)),"") -> 46274 | G29: =iferror(value(mid(D29,find("$",D29)+1,4)),"") -> 1
A30: =IFERROR(__xludf.DUMMYFUNCTION("""COMPUTED_VALUE"""),28.0) -> 28 | B30: =IFERROR(__xludf.DUMMYFUNCTION("""COMPUTED_VALUE"""),"The Meaty Ogres") -> The Meaty Ogres | C30: =IFERROR(__xludf.DUMMYFUNCTION("""COMPUTED_VALUE"""),"Waiver") -> Waiver | D30: =IFERROR(__xludf.DUMMYFUNCTION("""COMPUTED_VALUE"""),"- Acquired Tucker, Sean TBB RB for $34.00") -> - Acquired Tucker, Sean TBB RB for $34.00 | E30: =IFERROR(__xludf.DUMMYFUNCTION("""COMPUTED_VALUE"""),"Wed Sep 9 11:00:00 a.m. ET 2026") -> Wed Sep 9 11:00:00 a.m. ET 2026 | F30: =iferror(datevalue(left(E30,10)&right(E30,5)),"") -> 46274 | G30: =iferror(value(mid(D30,find("$",D30)+1,4)),"") -> 34
A31: =IFERROR(__xludf.DUMMYFUNCTION("""COMPUTED_VALUE"""),29.0) -> 29 | B31: =IFERROR(__xludf.DUMMYFUNCTION("""COMPUTED_VALUE"""),"Shankly's Ghost") -> Shankly's Ghost | C31: =IFERROR(__xludf.DUMMYFUNCTION("""COMPUTED_VALUE"""),"Waiver") -> Waiver | D31: =IFERROR(__xludf.DUMMYFUNCTION("""COMPUTED_VALUE"""),"- Acquired Flournoy, Ryan DAL WR for $51.00") -> - Acquired Flournoy, Ryan DAL WR for $51.00 | E31: =IFERROR(__xludf.DUMMYFUNCTION("""COMPUTED_VALUE"""),"Wed Sep 9 11:00:00 a.m. ET 2026") -> Wed Sep 9 11:00:00 a.m. ET 2026 | F31: =iferror(datevalue(left(E31,10)&right(E31,5)),"") -> 46274 | G31: =iferror(value(mid(D31,find("$",D31)+1,4)),"") -> 51
A32: =IFERROR(__xludf.DUMMYFUNCTION("""COMPUTED_VALUE"""),30.0) -> 30 | B32: =IFERROR(__xludf.DUMMYFUNCTION("""COMPUTED_VALUE"""),"The Meaty Ogres") -> The Meaty Ogres | C32: =IFERROR(__xludf.DUMMYFUNCTION("""COMPUTED_VALUE"""),"Waiver") -> Waiver | D32: =IFERROR(__xludf.DUMMYFUNCTION("""COMPUTED_VALUE"""),"- Acquired Kolar, Charlie LAC TE for $93.00") -> - Acquired Kolar, Charlie LAC TE for $93.00 | E32: =IFERROR(__xludf.DUMMYFUNCTION("""COMPUTED_VALUE"""),"Wed Sep 9 11:00:00 a.m. ET 2026") -> Wed Sep 9 11:00:00 a.m. ET 2026 | F32: =iferror(datevalue(left(E32,10)&right(E32,5)),"") -> 46274 | G32: =iferror(value(mid(D32,find("$",D32)+1,4)),"") -> 93
F33: =iferror(datevalue(left(E33,10)&right(E33,5)),"") | G33: =iferror(value(mid(D33,find("$",D33)+1,4)),"")
F34: =iferror(datevalue(left(E34,10)&right(E34,5)),"") | G34: =iferror(value(mid(D34,find("$",D34)+1,4)),"")
F35: =iferror(datevalue(left(E35,10)&right(E35,5)),"") | G35: =iferror(value(mid(D35,find("$",D35)+1,4)),"")
F36: =iferror(datevalue(left(E36,10)&right(E36,5)),"") | G36: =iferror(value(mid(D36,find("$",D36)+1,4)),"")
F37: =iferror(datevalue(left(E37,10)&right(E37,5)),"") | G37: =iferror(value(mid(D37,find("$",D37)+1,4)),"")
F38: =iferror(datevalue(left(E38,10)&right(E38,5)),"") | G38: =iferror(value(mid(D38,find("$",D38)+1,4)),"")
F39: =iferror(datevalue(left(E39,10)&right(E39,5)),"") | G39: =iferror(value(mid(D39,find("$",D39)+1,4)),"")
F40: =iferror(datevalue(left(E40,10)&right(E40,5)),"") | G40: =iferror(value(mid(D40,find("$",D40)+1,4)),"")
...

Sheet Notes
A1: Conditional Trades to Resolve
A2: BB has rights to swap 2026 5th round picks with PFB | E2: Done on 8/29

Sheet TokenAwards
A1: Entries for Wheel | B1: Team | C1: Tokens Given (Assuming min 50%) | D1: Entry Verification | E1: Odds for #1 | F1: Actual Draw Slot | G1: Prize Selected | I1: Available Awards
B2: The Wild Cards | C2: =Tracker!D2/2 -> 5.5 | D2: =countif($A:$A,B2) -> 0 | E2: =C2/sum(C:C) -> 0.052380952 | I2: 2026 Draft Pick 1.13
B3: Hamsterdam | C3: =Tracker!E2/2 -> 6.5 | D3: =countif($A:$A,B3) -> 0 | E3: =C3/sum(C:C) -> 0.061904762 | I3: 2027 Draft Pick 2.13
B4: Shankly's Ghost | C4: =Tracker!F2/2 -> 1.5 | D4: =countif($A:$A,B4) -> 0 | E4: =C4/sum(C:C) -> 0.014285714 | I4: 2026 Draft Pick 2.14
B5: 2 Roops, 1 Silva | C5: =Tracker!G2/2 -> 6 | D5: =countif($A:$A,B5) -> 0 | E5: =C5/sum(C:C) -> 0.057142857 | I5: 2027 Draft Pick 3.13
B6: Orcan Terror | C6: =Tracker!H2/2 -> 9 | D6: =countif($A:$A,B6) -> 0 | E6: =C6/sum(C:C) -> 0.085714286 | I6: 2026 Draft Pick 3.14
B7: The Meaty Ogres | C7: =Tracker!I2/2 -> 8 | D7: =countif($A:$A,B7) -> 0 | E7: =C7/sum(C:C) -> 0.076190476 | I7: 2026 Draft Pick 4th Rd - Draft pick forfeiture from Q2 Upper division relegation
B8: Ted Lasso | C8: =Tracker!J2/2 -> 1.5 | D8: =countif($A:$A,B8) -> 0 | E8: =C8/sum(C:C) -> 0.014285714 | I8: 2026 Draft Pick 4th Rd - Draft pick forfeiture from Q2 Middle division relegation
B9: Peaky Fookin Blinders | C9: =Tracker!K2/2 -> 0 | D9: =countif($A:$A,B9) -> 0 | E9: =C9/sum(C:C) -> 0 | I9: 2026 Draft Pick 3rd Rd - Draft pick forfeiture from Q3 Upper division relegation
B10: Springfield Isotopes | C10: =Tracker!L2/2 -> 10.5 | D10: =countif($A:$A,B10) -> 0 | E10: =C10/sum(C:C) -> 0.1 | I10: 2026 Draft Pick 3rd Rd - Draft pick forfeiture from Q3 Middle division relegation
B11: Battlebots | C11: =Tracker!M2/2 -> 43 | D11: =countif($A:$A,B11) -> 0 | E11: =C11/sum(C:C) -> 0.40952381 | I11: 50
B12: The Two Tones | C12: =Tracker!N2/2 -> 6 | D12: =countif($A:$A,B12) -> 0 | E12: =C12/sum(C:C) -> 0.057142857 | I12: Refund of Committed Tokens Back to Team
B13: Norsemen | C13: =Tracker!O2/2 -> 7.5 | D13: =countif($A:$A,B13) -> 0 | E13: =C13/sum(C:C) -> 0.071428571 | I13: 10 Tokens

Sheet RisersFalls
A1: Top 10 Risers
A2: =IFERROR(__xludf.DUMMYFUNCTION("sort(filter({PlayerValues!B2:B3222,PlayerValues!R2:R3222},PlayerValues!R2:R3222>large(PlayerValues!R2:R3222,11)),2,false)"),"#N/A") -> #N/A
A13: Top 10 Fallers
A14: =IFERROR(__xludf.DUMMYFUNCTION("sort(filter({PlayerValues!B2:B3222,PlayerValues!R2:R3222},PlayerValues!R2:R3222<small(PlayerValues!R2:R3222,11)),2,true)"),"Robinson, Bijan") -> Robinson, Bijan | B14: =IFERROR(__xludf.DUMMYFUNCTION("""COMPUTED_VALUE"""),-9998.0) -> -9998
A15: =IFERROR(__xludf.DUMMYFUNCTION("""COMPUTED_VALUE"""),"Gibbs, Jahmyr") -> Gibbs, Jahmyr | B15: =IFERROR(__xludf.DUMMYFUNCTION("""COMPUTED_VALUE"""),-9998.0) -> -9998
A16: =IFERROR(__xludf.DUMMYFUNCTION("""COMPUTED_VALUE"""),"Allen, Josh") -> Allen, Josh | B16: =IFERROR(__xludf.DUMMYFUNCTION("""COMPUTED_VALUE"""),-9993.0) -> -9993
A17: =IFERROR(__xludf.DUMMYFUNCTION("""COMPUTED_VALUE"""),"Chase, Ja'Marr") -> Chase, Ja'Marr | B17: =IFERROR(__xludf.DUMMYFUNCTION("""COMPUTED_VALUE"""),-9977.0) -> -9977
A18: =IFERROR(__xludf.DUMMYFUNCTION("""COMPUTED_VALUE"""),"Smith-Njigba, Jaxon") -> Smith-Njigba, Jaxon | B18: =IFERROR(__xludf.DUMMYFUNCTION("""COMPUTED_VALUE"""),-9195.0) -> -9195
A19: =IFERROR(__xludf.DUMMYFUNCTION("""COMPUTED_VALUE"""),"Bowers, Brock") -> Bowers, Brock | B19: =IFERROR(__xludf.DUMMYFUNCTION("""COMPUTED_VALUE"""),-9139.0) -> -9139
A20: =IFERROR(__xludf.DUMMYFUNCTION("""COMPUTED_VALUE"""),"Maye, Drake") -> Maye, Drake | B20: =IFERROR(__xludf.DUMMYFUNCTION("""COMPUTED_VALUE"""),-8897.0) -> -8897
A21: =IFERROR(__xludf.DUMMYFUNCTION("""COMPUTED_VALUE"""),"Nacua, Puka") -> Nacua, Puka | B21: =IFERROR(__xludf.DUMMYFUNCTION("""COMPUTED_VALUE"""),-8580.0) -> -8580
A22: =IFERROR(__xludf.DUMMYFUNCTION("""COMPUTED_VALUE"""),"St. Brown, Amon-Ra") -> St. Brown, Amon-Ra | B22: =IFERROR(__xludf.DUMMYFUNCTION("""COMPUTED_VALUE"""),-8188.0) -> -8188
A23: =IFERROR(__xludf.DUMMYFUNCTION("""COMPUTED_VALUE"""),"McBride, Trey") -> McBride, Trey | B23: =IFERROR(__xludf.DUMMYFUNCTION("""COMPUTED_VALUE"""),-8090.0) -> -8090

Sheet PlayerValues
A1: =IFERROR(__xludf.DUMMYFUNCTION("importrange(""https://docs.google.com/spreadsheets/d/1Sq384NvzuOA5vLi-wT_7CYoq3hD-kgu--fETQsusM8A"",""Current!A:D"")"),"#REF!") -> #REF! | E1: First Name Last | F1: 46023 | G1: =if(today()>=date(2026,month(F1)+1,1),date(2026,month(F1)+1,1),) -> 46054 | H1: =if(today()>=date(2026,month(G1)+1,1),date(2026,month(G1)+1,1),) -> 46082 | I1: =if(today()>=date(2026,month(H1)+1,1),date(2026,month(H1)+1,1),) -> 46113 | J1: =if(today()>=date(2026,month(I1)+1,1),date(2026,month(I1)+1,1),) -> 46143 | K1: =if(today()>=date(2026,month(J1)+1,1),date(2026,month(J1)+1,1),) -> 46174 | L1: =if(today()>=date(2026,month(K1)+1,1),date(2026,month(K1)+1,1),) -> 46204 | M1: =if(today()>=date(2026,month(L1)+1,1),date(2026,month(L1)+1,1),) -> 46235 | N1: =if(today()>=date(2026,month(M1)+1,1),date(2026,month(M1)+1,1),) -> 46266 | ... Q1: =if(today()>=date(2026,month(P1)+1,1),date(2026,month(P1)+1,1),) | R1: 1 Month Rise/Fall
A2: =IFERROR(__xludf.DUMMYFUNCTION("""COMPUTED_VALUE"""),151.0) -> 151 | B2: =IFERROR(__xludf.DUMMYFUNCTION("""COMPUTED_VALUE"""),"Bills, Buffalo") -> Bills, Buffalo | C2: =IFERROR(__xludf.DUMMYFUNCTION("""COMPUTED_VALUE"""),"TMWR") -> TMWR | D2: =IFERROR(__xludf.DUMMYFUNCTION("""COMPUTED_VALUE"""),"BUF") -> BUF | E2: =mid(B2,find(",",B2)+2,30)&" "&left(B2,find(",",B2)-1) -> Buffalo Bills | F2: =IF(isblank(F$1),,IF(isblank($A2),,IFERROR(vlookup($A2,indirect("'TVC-"&text(month(F$1),"00")&"'!$A:$D"),4,false),1))) -> 1 | G2: =IF(isblank(G$1),,IF(isblank($A2),,IFERROR(vlookup($A2,indirect("'TVC-"&text(month(G$1),"00")&"'!$A:$D"),4,false),1))) -> 1 | H2: =IF(isblank(H$1),,IFERROR(vlookup($A2,indirect("'TVC-"&text(month(H$1),"00")&"'!$A:$D"),4,false),1)) -> 1 | I2: =IF(isblank(I$1),,IFERROR(vlookup($A2,indirect("'TVC-"&text(month(I$1),"00")&"'!$A:$D"),4,false),1)) -> 1 | J2: =IF(isblank(J$1),,IFERROR(vlookup($A2,indirect("'TVC-"&text(month(J$1),"00")&"'!$A:$D"),4,false),1)) -> 1 | K2: =IF(isblank(K$1),,IFERROR(vlookup($A2,indirect("'TVC-"&text(month(K$1),"00")&"'!$A:$D"),4,false),1)) -> 1 | L2: =IF(isblank(L$1),,IFERROR(vlookup($A2,indirect("'TVC-"&text(month(L$1),"00")&"'!$A:$D"),4,false),1)) -> 1 | M2: =IF(isblank(M$1),,IFERROR(vlookup($A2,indirect("'TVC-"&text(month(M$1),"00")&"'!$A:$D"),4,false),1)) -> 1 | N2: =IF(isblank(N$1),,IFERROR(vlookup($A2,indirect("'TVC-"&text(month(N$1),"00")&"'!$A:$D"),4,false),1)) -> 1 | O2: =IF(isblank(O$1),,IFERROR(vlookup($A2,indirect("'TVC-"&text(month(O$1),"00")&"'!$A:$D"),4,false),1)) -> 1 | ... Q2: =IF(isblank(Q$1),,IFERROR(vlookup($A2,indirect("'TVC-"&text(month(Q$1),"00")&"'!$A:$D"),4,false),1)) | R2: =index(A2:Q2,,month(today())+5)-index(A2:Q2,,month(today())+4) -> 0
